Workbook

Sheet RESULTADO
A1: RESULTAT RONDA SOLAR 26/27 | H1: Grup Scout Parpalló
A4: RESUM
A5: Total d'ingressos anuals | E5: =(E35) -> 0
A6: Total de despeses anuals | E6: =(K35) -> 0
A8: SALDE COMPTES | E8: XXX
A10: DATA | E10: 46296
A16: INGRESSOS | G16: DESPESES
A18: 1. FINANÇAMENT | E18: =SUM(D19:D21) -> 0 | G18: 1. ASSEGURANÇA / QUOTA ASDE | K18: =SUM(J19) -> 0
A19: 1.1 Quotes | D19: =SUM(Cuotas!D:D) -> 0 | G19: 1.1 Quota ASDE | J19: =SUM(Cuotas!J:J) -> 0
A20: 1.2 Loteria | D20: =SUM('Lotería'!D:D) -> 0 | G20: 2. CAMPAMENTS | K20: =SUM(J21:J24) -> 0
A21: 1.3 Subvencions | G21: 2.1 Campament de Nadal | J21: =SUM('C. Navidad'!J:J) -> 0
A22: 2. CAMPAMENTS | E22: =SUM(D23:D26) -> 0 | G22: 2.2 Campament de Pasqua | J22: =SUM('C. Pascua'!J:J) -> 0
A23: 2.1 Campament de Nadal | D23: =SUM('C. Navidad'!D:D) -> 0 | G23: 2.3 Campament d´Estiu | J23: =SUM('C. Verano'!J:J) -> 0
A24: 2.2 Campament de Pasqua | D24: =SUM('C. Pascua'!D:D) -> 0 | G24: 2.4 SantJordi | J24: =SUM(SanJordi!J:J) -> 0
A25: 2.3 Campament d´Estiu | D25: =SUM('C. Verano'!D:D) -> 0 | G25: 3. GASTOS CORRENTS | K25: =SUM(J26:J28) -> 0
A26: 2.4 SantJordi | D26: =SUM(SanJordi!D:D) -> 0 | G26: 3.1 Loteria | J26: =SUM('Lotería'!J:J) -> 0
A27: 3. ACTIVITATS SECCIONS | E27: =SUM(D28:D31) -> 0 | G27: 3.2 Despeses activitats Secció
A28: 3.1 Estol | G28: 3.3 Suministres
A29: 3.2 Scout | G29: 4. MATERIAL DE GRUP | K29: =SUM(J30:J33) -> 0
A30: 3.3 Esculta | G30: 4.1 Infraestructura
A31: 3.4 Clan | G31: 4.2 Reforma del Local
A32: 4. ALTRES INGRESOS | E32: =SUM(D33) -> 0 | G32: 4.3 Material activitats
A33: 4.1 Roba | G33: 4.4 Terreny Benicoscoll
A34: 5. RESERVES PRÒPIES | G34: 5. ALTRES | K34: =K43 -> 0
A35: TOTAL | E35: =SUM(E18+E22+E27+E32+E34) -> 0 | G35: TOTAL | K35: =SUM(K18+K20+K25+K29+K34) -> 0
A37: 2.1 Campament de Nadal | E37: =SUM(D38:D40) -> 0 | G37: 3.2 Despeses activitats Secció | K37: =SUM(J38:J41) -> 0
A38: 2.1.1 Alberg | G38: 3.2.1 Estol
A39: 2.1.2 Autobús | G39: 3.2.2 Scout
A40: 2.1.3 Altres | G40: 3.2.3 Esculta
G41: 3.2.4 Clan
A42: 2.2 Campament de Pasqua | E42: =SUM(D43:D46) -> 0
A43: 2.1.1 Alberg / Terreny | G43: 5. Altres | K43: =SUM(J44:J50) -> 0
A44: 2.1.2 Autobús | G44: 5.1 Comunitat
A45: 2.1.3 Menjar | G45: 5.2 Cursos
A46: 2.1.4 Altres | G46: 5.3 Roba
G47: 5.4 Material Local
A48: 2.3 Campament d´Estiu | E48: =SUM(D49:D61) -> 0 | G48: 5.5 Wifi
A49: 2.3.1 Autobús | G49: 5.6 Convivència Scouters
A50: 2.3.2 Terreny | G50: 5.7 Altres
A51: 2.3.3 Camió
...

Sheet Cuotas
A1: INGRESO | G1: GASTOS
A2: Fecha de la operación | B2: Fecha valor | C2: Tipo movimiento | D2: Importe | E2: Saldo | G2: Fecha de la operación | H2: Fecha valor | I2: Tipo movimiento | J2: Importe | K2: Saldo

Sheet C. Navidad
A1: INGRESO | G1: GASTOS
A2: Fecha de la operación | B2: Fecha valor | C2: Tipo movimiento | D2: Importe | E2: Saldo | G2: Fecha de la operación | H2: Fecha valor | I2: Tipo movimiento | J2: Importe | K2: Saldo | L2: Concepto | M2: Explicación

Sheet Lotería
A1: INGRESO | G1: GASTOS
A2: Fecha de la operación | B2: Fecha valor | C2: Tipo movimiento | D2: Importe | E2: Saldo | G2: Fecha de la operación | H2: Fecha valor | I2: Tipo movimiento | J2: Importe | K2: Saldo

Sheet C. Pascua
A1: INGRESO | G1: GASTOS
A2: Fecha de la operación | B2: Fecha valor | C2: Tipo movimiento | D2: Importe | E2: Saldo | G2: Fecha de la operación | H2: Fecha valor | I2: Tipo movimiento | J2: Importe | K2: Saldo | L2: Concepto | M2: Explicación

Sheet SanJordi
A1: INGRESO | G1: GASTOS
A2: Fecha de la operación | B2: Fecha valor | C2: Tipo movimiento | D2: Importe | E2: Saldo | G2: Fecha de la operación | H2: Fecha valor | I2: Tipo movimiento | J2: Importe | K2: Saldo

Sheet C. Verano
A1: INGRESO | G1: GASTOS
A2: Fecha de la operación | B2: Fecha valor | C2: Tipo movimiento | D2: Importe | E2: Saldo | G2: Fecha de la operación | H2: Fecha valor | I2: Tipo movimiento | J2: Importe | K2: Saldo | L2: Concepto | M2: Explicación

Sheet Otras
A1: Fecha de la operación | B1: Fecha valor | C1: Tipo movimiento | D1: Importe | E1: Saldo | F1: Concepto
